

<?xml version="1.0"?>
<robot name="mobilni_robot">

  <!--urdf documentatition https://wiki.ros.org/urdf/XML -->
  <!-- xacro documentation https://wiki.ros.org/xacro -->

    <robot name="mobilni_robot" xmlns:xacro="http://www.ros.org/wiki/xacro">  <!--if we want a xacro file, this is mandatory-->

    <!--defining variables-->
    <xacro:property name="base_lenght" value="0.6"/>   <!-- calling a variable ${base_lenght}-->


    <!-- defining the material-->
    <material name="blue">
        <color rgba="0 0 0.5 1"/>
    </material>

    <material name="grey">
        <color rgba="0.5 0.5 0.5 1"/>
    </material>
  
  
  <!-- LINKOVI -->

  <xacro:macro name="wheel_link" params="prefix">  <!-- macro function     parameter is in this case only one and it is called prefix-->

  <link name="${prefix}_wheel_link">
        <visual>
            <geometry>
                <cylinder radius="${wheel_radius}" length="${wheel_length}" />
            </geometry>
            <origin xyz="0 0 0" rpy="${pi / 2.0} 0 0" />    <!--the position of the coordinate system with respect to the body itself-->
            <material name="grey" />
        </visual>
    </link> 
  </xacro:macro> <!-- closing the macro function is mandatory with this line of code-->

  <xacro:wheel_link prefix="right" />  <!-- macro function call example-->



   <link name="my_link">
       <inertial>
         <origin xyz="0 0 0.5" rpy="0 0 0"/>
         <mass value="1"/>
         <inertia ixx="100"  ixy="0"  ixz="0" iyy="100" iyz="0" izz="100" />
       </inertial>
    
       <visual>
         <origin xyz="0 0 0" rpy="0 0 0" />
        <geometry>
          <box size="1 1 1" />
        </geometry>
        <material name="Cyan">
          <color rgba="0 1.0 1.0 1.0"/>
        </material>
      </visual>
   
      <collision>
        <origin xyz="0 0 0" rpy="0 0 0"/>
        <geometry>
          <cylinder radius="1" length="0.5"/>
        </geometry>
      </collision>
    </link>

  <!-- JOINT KONFIGURACIJA -->
    <!-- https://wiki.ros.org/urdf/XML/joint -->
    <joint name="base_right_wheel_joint" type="continuous">
        <parent link="base_link"/>
        <child link="desni_kotac_link" />
        <origin xyz="-0.15 -0.225 0" rpy="0 0 0" />
        <axis xyz="0 1 0" />   
    </joint>

</robot>
