Toggle line numbers

<?xml version="1.0"?>
<robot name="mobilni_robot">
<!-- sve je u metrima -->


    <robot name="mobilni_robot" xmlns:xacro="http://www.ros.org/wiki/xacro">  <!--ako želimo xacro file obavezno ovo-->

    <!--definiranje varijabli-->
    <xacro:property name="base_lenght" value="0.6"/>   <!-- pozivanje varijable ${base_lenght}-->


    <!-- definiranje materijala-->
    <material name="blue">
        <color rgba="0 0 0.5 1"/>
    </material>

    <material name="grey">
        <color rgba="0.5 0.5 0.5 1"/>
    </material>
  
  
  <!-- LINKOVI -->

  <xacro:macro name="wheel_link" params="prefix">  <!-- makro sunkcija    parametar je u ovom slučaju samo jedan i naziva se prefix-->

  <link name="${prefix}_wheel_link">
        <visual>
            <geometry>
                <cylinder radius="${wheel_radius}" length="${wheel_length}" />
            </geometry>
            <origin xyz="0 0 0" rpy="${pi / 2.0} 0 0" /><!-- polozaj samog tijela u pripadajućem koordinatnom sustavu koji je pridijeljen tijelu
             rpy= role pitch yaw-->
            <!-- rotacije su u radijanima--> 
            <material name="grey" />
        </visual>
    </link> 
  </xacro:macro> <!-- zatvaranje macro funkcije je obavezno ovim redom koda-->

  <xacro:wheel_link prefix="right" />  <!-- primjer poziva macro funkcije-->



   <link name="my_link">
       <inertial>
         <origin xyz="0 0 0.5" rpy="0 0 0"/>
         <mass value="1"/>
         <inertia ixx="100"  ixy="0"  ixz="0" iyy="100" iyz="0" izz="100" />
       </inertial>
    
       <visual>
         <origin xyz="0 0 0" rpy="0 0 0" />
        <geometry>
          <box size="1 1 1" />
        </geometry>
        <material name="Cyan">
          <color rgba="0 1.0 1.0 1.0"/>
        </material>
      </visual>
   
      <collision>
        <origin xyz="0 0 0" rpy="0 0 0"/>
        <geometry>
          <cylinder radius="1" length="0.5"/>
        </geometry>
      </collision>
    </link>

  <!-- JOINT KONFIGURACIJA -->
    <!-- rotacije zglobova odnose se u odnosu na child koordinatni sustav
    dok se rotacije child u odnosu na parent definiraju tocno tako cild se rotira u koord sustavu parent-->
    <joint name="base_right_wheel_joint" type="continuous">
        <parent link="base_link"/>
        <child link="desni_kotac_link" />
        <origin xyz="-0.15 -0.225 0" rpy="0 0 0" />
        <axis xyz="0 1 0" />   
    </joint>

</robot>
